Traceback (most recent call last):
  File "c:\Users\chrism\Documents\My Stuff\Code\Predictions\Future-Generation-Station-main\Model Directory\\u2705TnP_merger.py", line 40, in <module>
    merged_df = merge_team_and_player_stats(player_df, team_df)
                ^^^^^^^^^^^^^^^^^^^^^^^^^^^^^^^^^^^^^^^^^^^^^^^
  File "c:\Users\chrism\Documents\My Stuff\Code\Predictions\Future-Generation-Station-main\Model Directory\\u2705TnP_merger.py", line 20, in merge_team_and_player_stats
    merged_df = pd.merge(
                ^^^^^^^^^
  File "C:\Users\chrism\AppData\Local\Programs\Python\Python311\Lib\site-packages\pandas\core\reshape\merge.py", line 170, in merge
    op = _MergeOperation(
         ^^^^^^^^^^^^^^^^
  File "C:\Users\chrism\AppData\Local\Programs\Python\Python311\Lib\site-packages\pandas\core\reshape\merge.py", line 794, in __init__
    ) = self._get_merge_keys()
        ^^^^^^^^^^^^^^^^^^^^^^
  File "C:\Users\chrism\AppData\Local\Programs\Python\Python311\Lib\site-packages\pandas\core\reshape\merge.py", line 1310, in _get_merge_keys
    left_keys.append(left._get_label_or_level_values(lk))
                     ^^^^^^^^^^^^^^^^^^^^^^^^^^^^^^^^^^^
  File "C:\Users\chrism\AppData\Local\Programs\Python\Python311\Lib\site-packages\pandas\core\generic.py", line 1911, in _get_label_or_level_values
    raise KeyError(key)
KeyError: 'TEAM_ID'
